testdata/golden/cancel-heavy.golden
replay v1 500 279 377 33 80 10
fill 0 6 5 99136 419 buy
fill 1 7 5 99136 88 buy
fill 2 7 4 99477 819 buy
fill 3 10 4 99477 90 buy
fill 4 10 1 99599 313 buy
fill 5 12 1 99599 263 buy
fill 6 12 11 100164 363 buy
fill 7 12 8 100308 100 buy
fill 8 12 9 100639 264 buy
fill 9 8 9 100639 177 buy
fill 10 14 8 100818 4 sell
fill 11 9 8 100818 198 sell
fill 12 8 13 100034 72 sell
fill 13 18 13 100034 83 sell
fill 14 21 13 100034 388 sell
fill 15 21 1 99907 93 sell
fill 16 24 22 99813 220 buy
fill 17 24 21 99815 265 buy
fill 18 22 21 99815 83 buy
fill 19 26 25 100076 559 buy
fill 20 26 17 100278 105 buy
fill 21 25 22 100015 14 sell
fill 22 25 16 99797 955 sell
fill 23 28 17 100278 131 buy
fill 24 28 19 100407 78 buy
fill 25 29 16 99797 43 sell
fill 26 29 27 99505 181 sell
fill 27 30 19 100407 577 buy
fill 28 30 23 100588 126 buy
fill 29 30 13 100721 116 buy
fill 30 31 17 100573 243 sell
fill 31 36 13 100721 159 buy
fill 32 37 17 100573 304 sell
fill 33 37 22 100354 674 sell
fill 34 16 22 100354 45 sell
fill 35 39 22 100301 410 sell
fill 36 23 22 100301 74 sell
fill 37 45 22 100301 155 sell
fill 38 45 33 99851 89 sell
fill 39 49 48 100326 44 buy
fill 40 41 33 99851 76 sell
fill 41 5 33 99851 280 sell
fill 42 5 47 99733 625 sell
fill 43 52 48 100326 506 buy
fill 44 52 16 100334 73 buy
fill 45 53 47 99733 182 sell
fill 46 55 54 99763 346 buy
fill 47 55 42 100231 310 buy
fill 48 56 47 99733 15 sell
fill 49 56 38 99684 438 sell
fill 50 56 46 99644 45 sell
fill 51 59 56 99538 461 buy
fill 52 59 19 99796 216 buy
fill 53 59 57 99993 154 buy
fill 54 62 61 99512 429 sell
fill 55 48 61 99512 57 sell
fill 56 48 27 99505 402 sell
fill 57 69 27 99505 9 sell
fill 58 69 65 99424 39 sell
fill 59 69 60 99401 176 sell
fill 60 33 66 99826 216 buy
fill 61 38 66 99826 49 buy
fill 62 70 38 99883 215 sell
fill 63 71 57 99993 392 buy
fill 64 72 57 99993 327 buy
fill 65 73 72 100174 147 sell
fill 66 73 38 99883 50 sell
fill 67 74 38 99883 515 sell
fill 68 75 63 100287 886 buy
fill 69 66 63 100287 54 buy
fill 70 66 16 100334 273 buy
fill 71 66 13 100700 94 buy
fill 72 66 42 100706 87 buy
fill 73 66 61 100731 262 buy
fill 74 66 15 100874 192 buy
fill 75 80 79 100410 818 sell
fill 76 81 79 100410 99 sell
fill 77 81 1 100064 161 sell
fill 78 81 77 100045 426 sell
fill 79 81 38 99883 101 sell
fill 80 81 76 99645 184 sell
fill 81 85 83 100365 404 buy
fill 82 92 88 100289 649 buy
fill 83 92 83 100365 344 buy
fill 84 93 83 100365 99 buy
fill 85 93 84 100449 65 buy
fill 86 93 47 100559 251 buy
fill 87 94 76 100276 205 sell
fill 88 94 82 100244 156 sell
fill 89 94 91 100121 6 sell
fill 90 97 91 100121 949 sell
fill 91 27 91 100121 43 sell
fill 92 27 96 100086 191 sell
fill 93 98 27 99977 8 buy
fill 94 87 98 100405 110 sell
fill 95 105 100 99894 66 sell
fill 96 105 101 99874 221 sell
fill 97 105 89 99830 464 sell
fill 98 105 104 99401 105 sell
fill 99 108 43 99596 406 buy
fill 100 109 43 99596 114 buy
fill 101 109 103 99721 511 buy
fill 102 111 34 99549 261 sell
fill 103 113 111 99448 547 buy
fill 104 78 95 99208 578 sell
fill 105 117 19 99167 303 sell
fill 106 117 102 99076 309 sell
fill 107 117 67 99058 284 sell
fill 108 72 78 99170 28 buy
fill 109 46 78 99170 111 buy
fill 110 46 111 99448 3 buy
fill 111 46 103 99721 289 buy
fill 112 46 110 99960 52 buy
fill 113 118 110 99960 467 buy
fill 114 120 107 100228 234 buy
fill 115 122 107 100228 700 buy
fill 116 124 122 100310 115 sell
fill 117 125 118 100144 289 sell
fill 118 126 125 99575 144 buy
fill 119 83 13 100039 534 buy
fill 120 83 124 100269 163 buy
fill 121 68 83 100431 136 sell
fill 122 68 127 99702 311 sell
fill 123 130 78 99878 314 sell
fill 124 131 130 99825 668 buy
fill 125 133 131 100330 258 sell
fill 126 133 127 99702 281 sell
fill 127 133 126 99678 24 sell
fill 128 61 126 99678 126 sell
fill 129 91 16 99779 724 buy
fill 130 91 47 100369 183 buy
fill 131 140 139 100058 149 sell
fill 132 142 139 100058 188 sell
fill 133 142 13 99791 495 sell
fill 134 143 84 100129 48 sell
fill 135 144 84 100129 151 sell
fill 136 146 84 100129 373 sell
fill 137 146 13 99791 370 sell
fill 138 146 138 99610 107 sell
fill 139 147 128 100526 577 buy
fill 140 151 150 100304 107 sell
fill 141 151 138 99610 76 sell
fill 142 152 138 99610 239 sell
fill 143 152 141 99597 559 sell
fill 144 154 153 99654 333 sell
fill 145 157 153 99654 588 sell
fill 146 157 141 99597 250 sell
fill 147 78 158 99707 81 sell
fill 148 78 156 99472 94 sell
fill 149 160 159 99775 400 sell
fill 150 160 156 99472 403 sell
fill 151 160 136 99276 143 sell
fill 152 162 136 99276 297 sell
fill 153 162 119 99266 153 sell
fill 154 166 162 99229 369 buy
fill 155 166 163 99320 520 buy
fill 156 166 161 99691 80 buy
fill 157 86 161 99691 381 buy
fill 158 167 165 99920 644 buy
fill 159 63 13 99903 491 sell
fill 160 63 86 99756 93 sell
fill 161 63 134 99206 86 sell
fill 162 169 165 99920 344 buy
fill 163 169 164 99957 116 buy
fill 164 171 169 100356 475 sell
fill 165 175 171 99894 40 buy
fill 166 175 128 100526 202 buy
fill 167 175 106 100552 712 buy
fill 168 177 86 100011 135 buy
fill 169 177 106 100552 271 buy
fill 170 177 155 100567 250 buy
fill 171 178 173 99811 243 sell
fill 172 180 155 100567 458 buy
fill 173 180 115 100573 423 buy
fill 174 158 3 100163 916 sell
fill 175 182 3 100163 77 sell
fill 176 182 173 99811 32 sell
fill 177 183 173 99811 362 sell
fill 178 183 176 99738 113 sell
fill 179 186 181 100421 188 buy
fill 180 186 115 100573 350 buy
fill 181 188 115 100573 60 buy
fill 182 188 35 100599 319 buy
fill 183 188 149 100631 402 buy
fill 184 190 189 100527 178 buy
fill 185 190 149 100631 260 buy
fill 186 190 148 100715 28 buy
fill 187 193 148 100715 434 buy
fill 188 193 132 100749 546 buy
fill 189 43 132 100749 364 buy
fill 190 43 65 100762 111 buy
fill 191 43 170 100859 524 buy
fill 192 56 181 100467 206 sell
fill 193 56 184 100418 425 sell
fill 194 56 192 100173 137 sell
fill 195 194 192 100173 218 sell
fill 196 196 192 100173 55 sell
fill 197 198 196 100092 256 buy
fill 198 199 197 100068 343 sell
fill 199 201 197 100068 181 sell
fill 200 201 121 100048 416 sell
fill 201 202 196 100092 274 buy
fill 202 202 200 100200 523 buy
fill 203 169 200 100200 160 buy
fill 204 60 119 100644 108 sell
fill 205 60 169 100285 305 sell
fill 206 209 169 100285 116 sell
fill 207 209 65 100198 335 sell
fill 208 210 208 100693 392 buy
fill 209 212 211 100499 741 sell
fill 210 212 65 100198 110 sell
fill 211 214 65 100198 511 sell
fill 212 214 207 100194 57 sell
fill 213 216 213 100175 602 sell
fill 214 216 42 99868 246 sell
fill 215 217 42 99868 111 sell
fill 216 219 217 99774 173 buy
fill 217 219 79 100006 50 buy
fill 218 221 176 99738 170 sell
fill 219 223 79 100006 862 buy
fill 220 224 223 100431 108 sell
fill 221 225 224 100086 454 buy
fill 222 225 98 100568 508 buy
fill 223 227 226 99969 160 buy
fill 224 229 176 99738 449 sell
fill 225 229 218 99682 224 sell
fill 226 1 226 99969 475 buy
fill 227 1 208 100219 480 buy
fill 228 90 208 100219 427 buy
fill 229 231 208 100219 8 buy
fill 230 231 98 100568 207 buy
fill 231 232 218 99682 308 sell
fill 232 232 215 99593 349 sell
fill 233 235 233 100103 17 sell
fill 234 236 98 100568 192 buy
fill 235 236 222 100625 712 buy
fill 236 125 124 100546 168 buy
fill 237 125 222 100625 142 buy
fill 238 125 32 100646 500 buy
fill 239 82 238 100213 613 sell
fill 240 242 241 100347 385 sell
fill 241 242 238 100213 110 sell
fill 242 242 116 100175 37 sell
fill 243 242 234 100026 48 sell
fill 244 242 237 99929 152 sell
fill 245 243 237 99929 202 sell
fill 246 243 228 99606 255 sell
fill 247 156 228 99606 362 sell
fill 248 156 215 99593 71 sell
fill 249 174 200 99437 327 sell
fill 250 132 174 99377 630 buy
fill 251 132 156 99540 335 buy
fill 252 124 156 99540 102 buy
fill 253 124 246 99746 387 buy
fill 254 13 246 99746 434 buy
fill 255 13 40 99785 469 buy
fill 256 251 239 99349 90 sell
fill 257 251 250 99286 406 sell
fill 258 253 40 99785 131 buy
fill 259 254 40 99785 218 buy
fill 260 256 40 99785 61 buy
fill 261 256 248 99832 412 buy
fill 262 256 245 99886 109 buy
fill 263 259 257 99455 244 buy
