testdata/golden/fifo_deep_queue.golden
replay v1 37 7 30 0 3 4
fill 0 31 1 100 5 sell
fill 1 31 2 100 2 sell
fill 2 32 2 100 3 sell
fill 3 32 3 100 5 sell
fill 4 32 4 100 5 sell
fill 5 33 6 100 2 sell
fill 6 34 6 100 1 sell
level buy 100 112 23 6:2,7:5,8:5,9:5,10:5,11:5,13:5,14:5,15:5,16:5,17:5,18:5,19:5,20:5,21:5,22:5,23:5,24:5,25:5,26:5,27:5,28:5,30:5
