testdata/golden/market-heavy.golden
replay v1 500 404 359 17 29 95
fill 0 6 4 100411 440 sell
fill 1 7 4 100267 299 buy
fill 2 7 6 100318 200 buy
fill 3 7 5 100455 231 buy
fill 4 6 1 99879 407 sell
fill 5 8 1 99879 220 sell
fill 6 8 3 99772 161 sell
fill 7 9 5 100455 542 buy
fill 8 12 9 100578 241 sell
fill 9 5 9 100578 77 sell
fill 10 5 14 100408 628 sell
fill 11 20 17 100688 338 sell
fill 12 20 14 100408 113 sell
fill 13 21 14 100408 214 sell
fill 14 21 19 100303 74 sell
fill 15 22 21 100294 308 buy
fill 16 24 3 99772 113 sell
fill 17 9 23 99874 34 buy
fill 18 25 3 99772 630 sell
fill 19 25 13 99744 25 sell
fill 20 26 23 99874 43 buy
fill 21 1 23 99874 15 buy
fill 22 1 21 100294 156 buy
fill 23 27 17 100080 662 buy
fill 24 27 21 100294 151 buy
fill 25 29 27 100492 62 sell
fill 26 29 28 100068 4 sell
fill 27 30 28 100068 313 sell
fill 28 32 28 100068 450 sell
fill 29 34 28 100068 126 sell
fill 30 34 33 99896 810 sell
fill 31 36 35 100185 699 sell
fill 32 38 35 100185 96 sell
fill 33 38 33 99896 168 sell
fill 34 38 13 99744 19 sell
fill 35 19 13 99744 364 sell
fill 36 42 3 100086 218 sell
fill 37 42 41 99965 553 sell
fill 38 21 40 100639 141 buy
fill 39 44 41 99965 178 sell
fill 40 44 13 99744 84 sell
fill 41 46 16 99666 826 sell
fill 42 47 16 99666 45 sell
fill 43 49 47 99604 384 buy
fill 44 51 39 99590 227 sell
fill 45 54 47 99604 482 buy
fill 46 54 44 99695 228 buy
fill 47 57 55 99948 207 sell
fill 48 58 55 99948 325 sell
fill 49 59 52 100445 176 buy
fill 50 60 55 99948 421 sell
fill 51 60 56 99922 460 sell
fill 52 61 52 100445 337 buy
fill 53 62 52 100445 203 buy
fill 54 62 40 100639 300 buy
fill 55 16 62 100670 272 sell
fill 56 16 56 99922 19 sell
fill 57 64 56 99922 116 sell
fill 58 64 44 99824 76 sell
fill 59 67 31 100765 562 buy
fill 60 68 17 100671 657 sell
fill 61 28 17 100671 324 sell
fill 62 69 66 100120 271 sell
fill 63 69 65 100043 346 sell
fill 64 69 54 99782 81 sell
fill 65 70 28 100527 40 buy
fill 66 70 41 100685 52 buy
fill 67 47 54 99782 34 sell
fill 68 47 63 99775 65 sell
fill 69 47 44 99730 250 sell
fill 70 72 39 99590 311 sell
fill 71 72 11 99586 148 sell
fill 72 73 11 99586 234 sell
fill 73 76 11 99586 467 sell
fill 74 76 18 99534 392 sell
fill 75 3 18 99534 63 sell
fill 76 80 48 99413 491 sell
fill 77 80 37 99309 141 sell
fill 78 82 3 99508 311 buy
fill 79 82 77 99655 600 buy
fill 80 82 47 99711 81 buy
fill 81 84 47 99711 261 buy
fill 82 84 83 100036 533 buy
fill 83 86 85 99611 92 sell
fill 84 86 81 99346 811 sell
fill 85 86 37 99309 77 sell
fill 86 89 37 99309 263 sell
fill 87 89 50 99274 385 sell
fill 88 92 90 99736 195 buy
fill 89 93 90 99736 82 buy
fill 90 93 91 99816 161 buy
fill 91 95 50 99274 538 sell
fill 92 95 45 99162 68 sell
fill 93 33 91 99816 38 buy
fill 94 33 83 100036 332 buy
fill 95 97 96 99790 198 buy
fill 96 99 44 99736 401 buy
fill 97 99 96 99790 81 buy
fill 98 55 98 99862 32 buy
fill 99 103 55 99931 73 sell
fill 100 103 45 99162 537 sell
fill 101 103 15 99102 205 sell
fill 102 105 104 99336 501 sell
fill 103 105 15 99102 133 sell
fill 104 107 83 99921 28 buy
fill 105 109 83 99921 18 buy
fill 106 110 106 99785 31 sell
fill 107 112 111 99897 196 buy
fill 108 113 111 99897 708 buy
fill 109 113 83 99921 218 buy
fill 110 115 83 99921 135 buy
fill 111 116 114 99838 439 sell
fill 112 117 114 99838 179 sell
fill 113 117 106 99785 31 sell
fill 114 117 108 99334 624 sell
fill 115 118 83 99921 72 buy
fill 116 118 96 99940 204 buy
fill 117 119 108 99334 103 sell
fill 118 119 15 99102 41 sell
fill 119 122 96 99940 441 buy
fill 120 122 121 99973 417 buy
fill 121 122 75 100229 71 buy
fill 122 123 120 99197 238 sell
fill 123 124 75 100229 572 buy
fill 124 125 75 100229 141 buy
fill 125 125 18 100328 61 buy
fill 126 125 87 100459 117 buy
fill 127 35 66 100006 675 sell
fill 128 53 66 100006 312 sell
fill 129 53 126 99517 351 sell
fill 130 129 126 99517 394 sell
fill 131 130 126 99517 40 sell
fill 132 130 120 99197 88 sell
fill 133 130 15 99102 308 sell
fill 134 134 75 99482 315 sell
fill 135 134 15 99102 217 sell
fill 136 135 133 99974 126 buy
fill 137 136 15 99102 8 sell
fill 138 138 136 98218 94 buy
fill 139 138 133 99974 125 buy
fill 140 139 133 99974 122 buy
fill 141 139 128 100117 429 buy
fill 142 141 137 97469 624 sell
fill 143 143 142 99693 624 sell
fill 144 144 140 99724 12 buy
fill 145 144 128 100117 364 buy
fill 146 144 55 100212 277 buy
fill 147 144 131 100348 152 buy
fill 148 147 146 100071 369 buy
fill 149 147 131 100348 11 buy
fill 150 133 148 100108 643 sell
fill 151 149 142 99693 78 sell
fill 152 150 133 99943 326 buy
fill 153 150 131 100348 141 buy
fill 154 151 131 100348 665 buy
fill 155 151 127 100432 158 buy
fill 156 151 87 100459 32 buy
fill 157 153 152 100371 360 sell
fill 158 154 142 99693 3 sell
fill 159 155 142 99693 213 sell
fill 160 155 106 99462 445 sell
fill 161 156 155 99071 317 buy
fill 162 127 153 99992 82 buy
fill 163 158 127 100123 49 sell
fill 164 160 158 99479 347 buy
fill 165 160 100 100008 552 buy
fill 166 37 156 99453 412 sell
fill 167 37 157 99392 66 sell
fill 168 162 157 99392 315 sell
fill 169 164 163 99451 3 buy
fill 170 164 100 100008 47 buy
fill 171 164 159 100406 487 buy
fill 172 164 87 100459 17 buy
fill 173 167 165 99477 271 sell
fill 174 167 157 99392 200 sell
fill 175 169 167 99373 415 buy
fill 176 169 158 99963 249 buy
fill 177 170 166 99204 28 sell
fill 178 171 166 99204 406 sell
fill 179 172 158 99963 274 buy
fill 180 172 87 100459 86 buy
fill 181 174 126 99566 43 sell
fill 182 158 87 100459 49 buy
fill 183 175 87 100459 107 buy
fill 184 175 78 100463 681 buy
fill 185 175 71 100472 5 buy
fill 186 176 126 99566 909 sell
fill 187 83 176 99358 80 buy
fill 188 83 71 100472 198 buy
fill 189 177 71 100472 12 buy
fill 190 181 178 99297 219 buy
fill 191 183 178 99297 209 buy
fill 192 184 178 99297 122 buy
fill 193 184 182 99363 35 buy
fill 194 185 182 99363 93 buy
fill 195 187 182 99363 562 buy
fill 196 188 173 99257 538 sell
fill 197 189 182 99363 31 buy
fill 198 190 182 99363 171 buy
fill 199 192 182 99363 42 buy
fill 200 192 111 99563 143 buy
fill 201 192 186 99788 762 buy
fill 202 23 186 99788 102 buy
fill 203 23 179 99821 530 buy
fill 204 152 179 99821 12 buy
fill 205 152 11 99855 314 buy
fill 206 194 11 99855 190 buy
fill 207 195 11 99855 258 buy
fill 208 195 193 100410 150 buy
fill 209 197 193 100410 41 buy
fill 210 155 131 99855 870 sell
fill 211 198 131 99855 26 sell
fill 212 200 198 99525 62 buy
fill 213 201 198 99525 577 buy
fill 214 201 193 100410 47 buy
fill 215 202 193 100410 90 buy
fill 216 202 71 100472 228 buy
fill 217 202 101 100500 450 buy
fill 218 205 199 99398 42 sell
fill 219 205 173 99257 149 sell
fill 220 205 180 99229 343 sell
fill 221 159 204 99843 835 buy
fill 222 208 206 99757 203 buy
fill 223 208 204 99843 41 buy
fill 224 208 101 100500 348 buy
fill 225 210 209 99626 186 sell
fill 226 211 209 99626 311 sell
fill 227 212 211 99363 185 buy
fill 228 212 106 100153 53 buy
fill 229 213 106 100153 275 buy
fill 230 215 213 100353 24 sell
fill 231 18 213 100353 241 sell
fill 232 18 180 99229 111 sell
fill 233 18 207 99224 335 sell
fill 234 146 101 100500 133 buy
fill 235 146 102 100506 329 buy
fill 236 146 75 100526 260 buy
fill 237 217 216 99412 176 sell
fill 238 218 217 99340 217 buy
fill 239 220 218 100073 494 sell
fill 240 223 220 99826 113 buy
fill 241 223 222 99948 203 buy
fill 242 225 222 99948 118 buy
fill 243 227 43 99643 642 buy
fill 244 228 43 99643 138 buy
fill 245 228 222 99948 282 buy
fill 246 229 222 99948 80 buy
fill 247 230 226 99617 10 sell
fill 248 231 222 99948 183 buy
fill 249 231 219 100250 244 buy
fill 250 231 75 100526 328 buy
fill 251 231 161 100526 64 buy
fill 252 234 161 100526 10 buy
fill 253 234 203 100604 134 buy
fill 254 234 2 100605 338 buy
fill 255 239 238 99789 379 buy
fill 256 240 232 99624 427 sell
fill 257 240 226 99617 568 sell
fill 258 243 238 99789 300 buy
fill 259 244 238 99789 234 buy
fill 260 244 2 100605 82 buy
fill 261 244 221 100610 138 buy
fill 262 245 244 100653 413 sell
fill 263 247 54 100197 98 buy
fill 264 249 54 100197 476 buy
fill 265 249 248 100397 16 buy
